Workbook

Sheet Read me
B1: Post-wall QC automation tracker
B2: 55 post-wall quality checks from the QC sheet, each mapped to the cheapest capture method that could automate it, with space to track the work.
B4: How to use this workbook
B5: QC Tracker | C5: One row per check. Columns A to L are copied from the QC sheet. Columns M to AD hold the proposed design for each check. Columns AE to AK (yellow) are yours to fill as work progresses. Filter and sort with the header buttons. The + controls above the columns collapse Stage/Task and the flag columns, leaving the check text, the design and the tracking in view.
B6: Methods | C6: The method codes used in the tracker: what each asks of the site engineer, the added seconds it costs (blue cells, estimates you can edit) and the accuracy to expect. Changing a time here updates the tracker and the dashboard.
B7: Dashboard | C7: Counts by status, method, automation level, confidence, check family and stage. Formulas only; nothing to type.
B8: Experiments | C8: A log of what was tried and decided. The first row is an example to overwrite.
B9: Source data | C9: The QC sheet export as received, for reference. Columns left out of the tracker: those identical on every row (Phase, Removal Status, GYRO+AI, 2D PHONE+AI, AI_NOT_ENABLED, measurement_type, hierarchy, 2_0_measurement_type), empty ones (capture_type, 2.0 Current, measurement_config) and admin fields (config_updated_on, stage_id, task_id, 2_0_measurement_config, qc_category, task_type).
B11: Legend
B12: Yellow fill | C12: Cells for the team to fill in.
B13: Blue text | C13: An estimate you can change (Methods tab, column D).
B14: Green text | C14: A formula that reads another tab.
B15: Grey text | C15: Copied from the QC sheet; edit it there.
B17: Definitions used in the tracker
B18: Full | C18: The capture, plus at most one requested photo, decides pass or fail. The SE reviews flags only.
B19: Partial | C19: The system screens and flags. The SE confirms borderline cases, or part of the check stays manual.
B20: Evidence | C20: The system records proof or an approval. The judgement stays with a person.
B21: Manual | C21: Stays with the SE and a physical tool. The app records the reading.
B22: Confidence | C22: How likely the primary method reaches useful accuracy in production with the current gyro capture: High, Medium or Low.
B23: Same detector as | C23: The ID of the check whose detector also serves this row. Build it once and run it at both stages.
B24: ARCore relevance | C24: Core: the measurement relies on ARCore poses, gravity, the floor plane or wall planes. Helps: better accuracy or robustness, but the check works without it. No: ARCore adds nothing to this check.
B25: Approach group | C25: The team's own plan for the check, in nine groups. Four gyro groups split by what Gemini has to judge: appearance (presence, finish, type), geometry (angles, plumb, level, alignment), height, or a known object used as the scale. Three new-action groups by what the SE does: phone IMU, a photo with the tape or tool in place, or a short video. Then Not a QC, and To be decided.
B26: SE columns | C26: SE Comments, Accuracy Requirements SE and Feasibility with Gyro are the site engineer's own notes, carried over from the tracker export.
B27: Distinct detectors | C27: =Dashboard!B6&" detectors cover "&Dashboard!B5&" checks." -> 42 detectors cover 55 checks.
B29: Proposed pipeline from the existing gyro capture
B30: 1. Gravity-align every frame with the gyro and accelerometer, then stitch the bands into one equirectangular panorama. The phone turns about a fixed point on the tripod, so stitching is a pure-rotation problem and is reliable.
B31: 2. Run a room-layout model on the panorama to get the floor and ceiling boundaries and the corners. Set the metric scale from the camera height: either fix the tripod height (a mark on the stick) or let the app derive it from the floor-to-ceiling height in the drawing. No new site action is needed.
B32: 3. Re-project the panorama into one flat elevation image per wall and one top-down image of the floor. Straight lines stay straight in these views, which the measurement checks rely on, and vision models read them better than a distorted panorama.
B33: 4. Detect the elements each check needs (openings, boxes, pipe stubs, bands, skirting, tiles, grills, columns) and convert pixel positions to millimetres with the wall distance from step 2. Known objects in the scene (block height, tile size) give a second, finer scale.
B34: 5. Send each check's crop, the drawing or specification values and the standard-heights table to the vision model with a check-specific prompt. It returns pass, flag or needs-a-photo.
B35: 6. Only when a check needs it, the app asks the SE for one close-up photo (TAP) or a one-tap confirmation (ATTEST). The added site time stays at seconds per room.
B37: Using ARCore on the capture device
B38: Start the session at the door and walk to the tripod position with the camera on. Pure rotation on a tripod gives visual-inertial tracking nothing to work with; the walk-in sets the scale, finds the floor plane and usually some walls.
B39: Take from ARCore: the pose of every frame in a gravity-aligned world frame, the floor plane (camera height, with no fixed tripod height or ceiling height needed), calibrated intrinsics, and a session recording for cloud processing.
B40: Grab full-resolution stills through the shared camera and match them to poses by timestamp. ARCore's own image is 1 to 2 MP, which halves the measurement resolution.
B41: Depth-from-motion does not work during the sweep, and plane detection fails on painted walls. Tags on the datum line remain the reliable wall anchor at the putty and paint stages and wherever ±10 mm is wanted.
... B46: What one viewpoint can and cannot do
B47: Heights and positions on a wall (G-GEO) | C47: About ±20–30 mm at 3 m; about ±5 mm with a tile or block as the ruler. Enough for standard heights, lintel and sill heights, skirting, the waterproofing line and box positions.
B48: Plumb and level of edges (G-PLUMB) | C48: About ±0.2°, which is ±7 mm over 2 m. Screens for gross errors; not a replacement for a plumb bob at ±3 mm.
B49: Alignment on the floor (G-FLOOR) | C49: About 1 mm with the tile as the ruler. Grout-line alignment and pattern.
...

Sheet QC Tracker
A1: From your QC sheet (trimmed to the useful columns) | M1: Proposed automation design | AE1: Your tracking (fill in) | AL1: Ref
A2: ID (sno) | B2: Stage | C2: Task | D2: QC check | E2: Sub-phase | F2: Current SE method | G2: Priority | H2: No-go | I2: Level (2.0) | J2: Stage type | K2: In 2.0 | L2: Live today | M2: Check family | N2: What to measure or judge | O2: SE Comments | P2: Accuracy Requirements SE | Q2: Primary method | R2: Automation level | S2: Confidence | T2: Feasibility with Gyro | U2: Approach group | V2: Approach description | W2: How it would work | X2: ARCore relevance | Y2: How ARCore helps | Z2: Fallback or upgrade | AA2: Inputs the prompt needs | AB2: Target tolerance (typical; confirm against your spec) | AC2: Same detector as (ID) | AD2: Extra SE time (s) | AE2: Status | AF2: Owner | AG2: Target sprint | AH2: Validation accuracy | AI2: Validation sample (n) | AJ2: Last updated | AK2: Notes | AL2: qc_id
A3: 30 | B3: Casting the lintels,staircase, blockwork upto the slab level | C3: Blockwork upto Beam/Slab bottom level | D3: All the openings are at right angles and are vertical. | E3: PostWall Non Putty | F3: Tools | G3: CRITICAL | H3: No | I3: Space | J3: Floorwise | K3: Yes | L3: Yes | M3: Squareness and plumb | N3: Jamb lean against gravity; jamb-to-soffit angle, per opening. | O3: Use All Gyro three Angles for this | Q3: G-PLUMB | R3: Partial | S3: Medium | T3: High | U3: Gyro + Gemini: geometry | V3: Select the gyro frames that show the openings; Gemini checks for right angles. | W3: Gravity-align the frames with the gyro, rectify each wall to a flat elevation view and detect the opening edges. Jambs should be vertical and the soffit horizontal; report the lean in mm over the opening height and the corner angle. Flags go to the SE. | X3: Helps | Y3: Gravity-aligned world frame gives the vertical reference in every frame, and the poses tie the bands so the full jamb height sits in one wall view. Gravity is good to about 0.1–0.3°, so this stays a screening check. | Z3: BT-TOOL digital level on flagged openings only. The vertical vanishing point of the room's own edges can refine the gyro's gravity estimate. | AA3: Plumb tolerance. | AB3: Plumb within 5 mm over the opening height; 90° ± 0.5° | AD3: =INDEX(Methods!$D$2:$D$11,MATCH(Q3,Methods!$A$2:$A$11,0)) -> 0 | AE3: Not started | AL3: ff808081818cac9e01818cb0c02e0051
A4: 31 | B4: Casting the lintels,staircase, blockwork upto the slab level | C4: Blockwork upto Beam/Slab bottom level | D4: Blockwork has been checked in vertical and horizontal directions and is found to be straight. | E4: PostWall Non Putty | F4: Tools | G4: CRITICAL | H4: No | I4: Wall | J4: Floorwise | K4: Yes | L4: Yes | M4: Alignment and straightness | N4: Straightness of courses (horizontal) and perpends or wall ends (vertical) in the wall plane. | O4: Critical has to be accurate | P4: 5mm to 10mm | Q4: G-PLUMB | R4: Partial | S4: Medium | T4: Low | U4: New action: phone IMU | V4: Use the phone IMU, or have the SE take a photo with the tool placed on the wall. | W4: On the rectified wall view, detect the mortar lines, fit straight lines and report the largest deviation; the block height gives the mm scale. This checks in-plane alignment. A bow toward or away from the camera is not visible from one viewpoint. | X4: Helps | Y4: Poses give the flat per-wall view and tie the bands. Blockwork is textured enough for vertical-plane detection, which supplies the wall plane for that view. | Z4: Straightedge by the SE on flagged walls; a BT laser meter read at three points along the wall gives the bow. | AA4: Block size (mm); straightness tolerance. | AB4: About 6 mm over 3 m | AD4: =INDEX(Methods!$D$2:$D$11,MATCH(Q4,Methods!$A$2:$A$11,0)) -> 0 | AE4: Not started | AL4: ff808081818cac9e01818cb0c02e0052
A5: 33 | B5: Casting the lintels,staircase, blockwork upto the slab level | C5: Blockwork upto Beam/Slab bottom level | D5: Check for plumb in door and window openings | E5: PostWall Non Putty | F5: Tools | G5: CRITICAL | H5: No | I5: Space | J5: Floorwise | K5: Yes | L5: Yes | M5: Plumb and level | N5: Jamb lean against gravity. | P5: 5mm to 10mm | Q5: G-PLUMB | R5: Partial | S5: Medium | T5: Low | U5: New action: phone IMU | V5: Use the phone IMU, or have the SE take a photo with the tool placed in the opening. | W5: Same detector as ID 30: this is the vertical component of the opening check. | X5: Helps | Y5: Same as ID 30: gravity reference and band linkage. | Z5: BT-TOOL on flagged openings. | AA5: Plumb tolerance. | AB5: Within 5 mm over the opening height | AC5: 30 | AD5: =INDEX(Methods!$D$2:$D$11,MATCH(Q5,Methods!$A$2:$A$11,0)) -> 0 | AE5: Not started | AL5: ff808081818cac9e01818cb0c02e0055
A6: 34 | B6: Casting the lintels,staircase, blockwork upto the slab level | C6: Blockwork upto Beam/Slab bottom level | D6: concrete band is provided at the height of 4feet as per standards | E6: PostWall Non Putty | F6: Tape | G6: REGULAR | H6: No | I6: Space | J6: Floorwise | K6: Yes | L6: Yes | M6: Height and position | N6: Height of the band's top and bottom edges above floor level, per wall. | P6: 3ft-4ft | Q6: G-GEO | R6: Full | S6: High | T6: Low | U6: New action: photo with tape or tool | V6: SE takes a photo with the measuring tape held against the band. | W6: The band is a distinct concrete strip in the blockwork. Segment it on each rectified wall and convert its edges to heights using the camera height and the wall distance from the room layout. Compare with 1200 mm. | X6: Core | Y6: Floor plane gives the camera height and a floor reference even where the junction is hidden; poses and intrinsics turn the band's edges into heights. | Z6: TAP photo with a tape held against the band. | AA6: Band height standard (1200 mm); band depth from the structural drawing. | AB6: 1200 mm ± 25 mm | AD6: =INDEX(Methods!$D$2:$D$11,MATCH(Q6,Methods!$A$2:$A$11,0)) -> 0 | AE6: Not started | AL6: cd843141-8f6e-4561-8586-35477991dd9e
A7: 36 | B7: Casting the lintels,staircase, blockwork upto the slab level | C7: Blockwork upto Beam/Slab bottom level | D7: Mortar thickness is checked and is found to be ok. | E7: PostWall Non Putty | F7: Tape | G7: REGULAR | H7: No | I7: Space | J7: Floorwise | K7: Yes | L7: Yes | M7: Thickness and joints | N7: Average and local mortar joint thickness. | P7: 10mm to 15mm | Q7: G-GEO | R7: Partial | S7: Medium | T7: High | U7: Gyro + Gemini: known object as scale | V7: Blocks come in about 10 types. Gemini identifies the block type and judges the mortar thickness relative to the block; one block type has no mortar. | W7: Average joint = course pitch minus block height, measured over several courses on the rectified wall (the block is the ruler). Local joints wider than about 15 mm show at 1 mm per pixel; finer differences do not. | X7: Helps | Y7: Vertical-plane detection on blockwork gives the mm-per-pixel scale on the wall. The block height remains the finer ruler. | Z7: TAP close-up with a block edge in frame for exact joints. Thin-bed AAC joints (3–4 mm) always need the close-up. | AA7: Block height (mm); mortar type (conventional or thin-bed). | AB7: 10 mm ± 3 mm conventional; 3–4 mm thin-bed | AD7: =INDEX(Methods!$D$2:$D$11,MATCH(Q7,Methods!$A$2:$A$11,0)) -> 0 | AE7: Not started | AL7: ff808081818cac9e01818cb0c02e0053
A8: 37 | B8: Casting the lintels,staircase, blockwork upto the slab level | C8: Blockwork upto Beam/Slab bottom level | D8: Sofit of the doors and windows are in tube level | E8: PostWall Non Putty | F8: Tools | G8: REGULAR | H8: No | I8: Space | J8: Floorwise | K8: Yes | L8: Yes | M8: Plumb and level | N8: Soffit height of every opening; soffit line horizontal. | Q8: G-GEO | R8: Partial | S8: Medium | T8: High | U8: Gyro + Gemini: geometry | V8: Select the gyro frames that show the openings; Gemini checks the soffits for level, same frames as the right-angle check. | W8: Soffit heights from the rectified walls (about ±20 mm) compared across all openings in the room, and each soffit line checked against gravity. Catches an opening set 30 mm high; cannot match a tube level's millimetres. | X8: Core | Y8: Gravity frame defines horizontal and the floor plane fixes one height datum, so soffit heights across openings and walls share a reference. | Z8: BT laser level or digital level on flagged openings. | AA8: Lintel height from the drawing. | AB8: Within 10 mm between openings | AD8: =INDEX(Methods!$D$2:$D$11,MATCH(Q8,Methods!$A$2:$A$11,0)) -> 0 | AE8: Not started | AL8: c5d36f17-44a3-476d-946c-0423ce285889
A9: 38 | B9: Casting the lintels,staircase, blockwork upto the slab level | C9: Blockwork upto Beam/Slab bottom level | D9: Verticality of the column is checked above the lintel | E9: PostWall Non Putty | F9: Tools | G9: REGULAR | H9: No | I9: Space | J9: Floorwise | K9: Yes | L9: Yes | M9: Plumb and level | N9: Column edge lean against gravity above lintel level. | Q9: G-PLUMB | R9: Partial | S9: Medium | T9: Low | U9: New action: phone IMU | V9: Place the phone's edge against the column at the joint above the lintel and read the tilt. | W9: Columns read as concrete against blockwork before plaster. Detect both edges on the rectified wall view and measure the lean over the visible height. | X9: Helps | Y9: Gravity reference for the column edges; poses tie the bands over the column's height. | Z9: BT-TOOL or plumb bob on flagged columns. | AA9: Column plumb tolerance from the structural spec. | AB9: Per structural spec | AD9: =INDEX(Methods!$D$2:$D$11,MATCH(Q9,Methods!$A$2:$A$11,0)) -> 0 | AE9: Not started | AL9: df23d09d-c89f-42e5-a4d8-57e704290479
A10: 40 | B10: Casting the lintels,staircase, blockwork upto the slab level | C10: During Lintel casting and curing | D10: All the Lintels at the openings are placed at standards heights as per the drawing | E10: PostWall Non Putty | F10: Tape | G10: REGULAR | H10: No | I10: Space | J10: Floorwise | K10: Yes | L10: Yes | M10: Height and position | N10: Lintel soffit height above floor, per opening. | P10: 7ft (Depends on the door/window size) | Q10: G-GEO | R10: Full | S10: High | T10: Low | U10: New action: photo with tape or tool | V10: SE takes a photo with the measuring tape from floor to lintel. | W10: Lintel soffit height from the rectified wall view against the height given in the drawing for that opening. | X10: Core | Y10: Floor plane gives the height reference; poses and intrinsics give the soffit height per opening. | Z10: TAP with a tape. | AA10: Lintel heights from the drawing (for example 2100 mm). | AB10: ± 25 mm | AD10: =INDEX(Methods!$D$2:$D$11,MATCH(Q10,Methods!$A$2:$A$11,0)) -> 0 | AE10: Not started | AL10: fa098a6a-46e0-44ff-9383-9b350dcc700b
A11: 63 | B11: Casting the lintels,staircase, blockwork upto the slab level | C11: Lintel Shuttering and Reinforcement | D11: Standard lintel dimension has been maintained as per structural drawing. | E11: PostWall Non Putty | F11: Tape | G11: REGULAR | H11: No | I11: Space | J11: Floorwise | K11: Yes | L11: Yes | M11: Size against drawing | N11: Lintel depth and bearing length each side; width equals the wall thickness. | Q11: G-GEO | R11: Partial | S11: Medium | T11: Low | U11: New action: photo with tape or tool | V11: SE takes a photo with the measuring tape across the lintel. | W11: Depth and bearing are visible as the concrete band around the opening before plaster; measure them on the rectified wall (about ±10–20 mm). Width cannot be seen from inside the room. | X11: Core | Y11: Wall plane distance (plane detection or a tag) with the intrinsics gives lintel depth and bearing in mm. | Z11: TAP with a tape across the lintel. | AA11: Structural drawing (depth, bearing). | AB11: ± 10 mm | AD11: =INDEX(Methods!$D$2:$D$11,MATCH(Q11,Methods!$A$2:$A$11,0)) -> 0 | AE11: Not started | AL11: 8a7483bc8adaa888018add7add9d0004
A12: 69 | B12: Casting the lintels,staircase, blockwork upto the slab level | C12: Staircase During Concreting | D12: Concrete is compacted properly using vibrators. | E12: PostWall Non Putty | F12: Tools | G12: CRITICAL | H12: Yes | I12: Space | J12: Floorwise | K12: Yes | L12: Yes | M12: Process and approval | N12: Vibrator used during the pour; no honeycombing after deshuttering. | P12: Turn on vibrator before starting gyro | Q12: ATTEST | R12: Evidence | S12: Medium | T12: Low | U12: New action: short video | V12: Short video focused on the concreting with the vibrator running. SE: turn the vibrator on before starting the gyro. | W12: During the pour, a mandatory ten-second video or photo of the vibrator in use. After deshuttering, the staircase gyro frames go through the vision model for honeycombing, voids and segregation on the waist slab, risers and soffit. | X12: No | Y12: A process record. Honeycomb screening after deshuttering uses the ordinary frames. | Z12: TAP close-ups of suspect patches. | AA12: None. | AB12: No honeycombing visible | AD12: =INDEX(Methods!$D$2:$D$11,MATCH(Q12,Methods!$A$2:$A$11,0)) -> 10 | AE12: Not started | AL12: ff808081818cac9e01818cb0c02d004c
A13: 72 | B13: Column rising, blockwork upto lintel level | C13: Blockwork base course | D13: Blockwork has been checked in vertical and horizontal directions and is found to be straight. | E13: PostWall Non Putty | F13: Tools | G13: CRITICAL | H13: No | I13: Space | J13: Floorwise | K13: Yes | L13: Yes | M13: Alignment and straightness | N13: Straightness of the base course in both directions. | O13: Critical has to be accurate | P13: 5mm to 10mm | Q13: G-PLUMB | R13: Partial | S13: Medium | T13: Low | U13: New action: phone IMU | V13: Use the phone IMU, or have the SE take a photo with the tool placed on the wall. | W13: Same detector as ID 31, run at the base-course stage. | X13: Helps | Y13: Same as ID 31. | Z13: Straightedge on flagged walls. | AA13: Block size (mm). | AB13: About 6 mm over 3 m | AC13: 31 | AD13: =INDEX(Methods!$D$2:$D$11,MATCH(Q13,Methods!$A$2:$A$11,0)) -> 0 | AE13: Not started | AL13: ff808081818cac9e01818cb0c02e0052
A14: 76 | B14: Column rising, blockwork upto lintel level | C14: Blockwork base course | D14: Mortar thickness is checked and is found to be ok. | E14: PostWall Non Putty | F14: Tape | G14: REGULAR | H14: No | I14: Space | J14: Floorwise | K14: Yes | L14: Yes | M14: Thickness and joints | N14: Average and local mortar joint thickness at the base course. | P14: 10mm to 15mm | Q14: G-GEO | R14: Partial | S14: Medium | T14: High | U14: Gyro + Gemini: known object as scale | V14: Blocks come in about 10 types. Gemini identifies the block type and judges the mortar thickness relative to the block; one block type has no mortar. | W14: Same detector as ID 36, run at the base-course stage. | X14: Helps | Y14: Same as ID 36. | Z14: TAP close-up with a block edge in frame. | AA14: Block height (mm); mortar type. | AB14: 10 mm ± 3 mm conventional | AC14: 36 | AD14: =INDEX(Methods!$D$2:$D$11,MATCH(Q14,Methods!$A$2:$A$11,0)) -> 0 | AE14: Not started | AL14: ff808081818cac9e01818cb0c02e0053
A15: 77 | B15: Column rising, blockwork upto lintel level | C15: Blockwork upto Lintel | D15: All the openings are at right angles and are vertical. | E15: PostWall Non Putty | F15: Tools | G15: CRITICAL | H15: No | I15: Space | J15: Floorwise | K15: Yes | L15: Yes | M15: Squareness and plumb | N15: Jamb lean and jamb-to-soffit angle, per opening. | P15: Use All Gyro three Angles for this | Q15: G-PLUMB | R15: Partial | S15: Medium | T15: High | U15: Gyro + Gemini: geometry | V15: Select the gyro frames that show the openings; Gemini checks for right angles. | W15: Same detector as ID 30, run at the lintel-level stage. | X15: Helps | Y15: Same as ID 30. | Z15: BT-TOOL on flagged openings. | AA15: Plumb tolerance. | AB15: Within 5 mm; 90° ± 0.5° | AC15: 30 | AD15: =INDEX(Methods!$D$2:$D$11,MATCH(Q15,Methods!$A$2:$A$11,0)) -> 0 | AE15: Not started | AL15: ff808081818cac9e01818cb0c02e0051
A16: 79 | B16: Column rising, blockwork upto lintel level | C16: Blockwork upto Lintel | D16: Check for plumb in door and window openings | E16: PostWall Non Putty | F16: Tools | G16: CRITICAL | H16: No | I16: Space | J16: Floorwise | K16: Yes | L16: Yes | M16: Plumb and level | N16: Jamb lean against gravity. | P16: 5mm to 10mm | Q16: G-PLUMB | R16: Partial | S16: Medium | T16: Low | U16: New action: phone IMU | V16: Use the phone IMU, or have the SE take a photo with the tool placed in the opening. | W16: Same detector as ID 30 (vertical component), run at the lintel-level stage. | X16: Helps | Y16: Same as ID 30. | Z16: BT-TOOL on flagged openings. | AA16: Plumb tolerance. | AB16: Within 5 mm over the opening height | AC16: 30 | AD16: =INDEX(Methods!$D$2:$D$11,MATCH(Q16,Methods!$A$2:$A$11,0)) -> 0 | AE16: Not started | AL16: ff808081818cac9e01818cb0c02e0055
A17: 83 | B17: Column rising, blockwork upto lintel level | C17: Blockwork upto Lintel | D17: Sill concrete is provided at the standrad height as per drawing/Spec | E17: PostWall Non Putty | F17: Tape | G17: REGULAR | H17: No | I17: Space | J17: Floorwise | K17: Yes | L17: Yes | M17: Height and position | N17: Sill top height above floor, per window. | P17: 3ft-4ft | Q17: G-GEO | R17: Full | S17: High | T17: Low | U17: To be decided | W17: The sill band is visible before plaster. Height of its top edge on the rectified wall against the drawing. | X17: Core | Y17: Floor plane gives the height reference for the sill top; poses and intrinsics do the conversion. | Z17: TAP with a tape. | AA17: Sill heights from the drawing (for example 900 mm). | AB17: ± 25 mm | AD17: =INDEX(Methods!$D$2:$D$11,MATCH(Q17,Methods!$A$2:$A$11,0)) -> 0 | AE17: Not started | AL17: 383aa31e-d270-4190-b755-653c93a94b0b
A18: 84 | B18: Column rising, blockwork upto lintel level | C18: Blockwork upto Lintel | D18: Verticality of the walls has been checked and is good to go. | E18: PostWall Non Putty | F18: Tools | G18: CRITICAL | H18: No | I18: Space | J18: Floorwise | K18: Yes | L18: Yes | M18: Plumb and level | N18: Wall lean. | Q18: G-PLUMB | R18: Partial | S18: Medium | T18: Low | U18: New action: phone IMU | V18: Place the phone flat against the wall at two or three points and read the tilt. | W18: Corner lines checked against gravity. A lean toward or away from the camera does not show as a slanted line, so also compare each wall's floor-line and ceiling-line distances from the layout; the difference is the lean over the full height (resolves about 30 mm). | X18: Helps | Y18: Vertical-plane detection returns each wall's normal; its angle to gravity is the lean, independent of edge detection. Plane normals are good to roughly 0.5–1°, so screening only, and detection fails on untextured walls. | Z18: BT-TOOL digital level or plumb bob on flagged walls. | AA18: Plumb tolerance. | AB18: About 6 mm per 3 m | AD18: =INDEX(Methods!$D$2:$D$11,MATCH(Q18,Methods!$A$2:$A$11,0)) -> 0 | AE18: Not started | AL18: ff808081818cac9e01818cb0c02e0054
A19: 107 | B19: Compound wall | C19: Block work and plastering compound wall | D19: Buttress in masonry or concrete at regular intervals has been provided to avoid long length of compound wall | E19: COMPOUND WALL(Post Wall) | F19: Tape | G19: CRITICAL | H19: No | J19: One-time | K19: No | L19: No | M19: Presence and spec match | N19: Buttress count and spacing along the compound wall. | Q19: EXT | R19: Partial | S19: Medium | T19: Low | U19: To be decided | W19: A walking video along the compound wall, or gyro captures at two or three points in the plot. Detect the buttresses, count them and get the spacing from the wall length in the plot drawing. | X19: Helps | Y19: Outdoors, ARCore tracks the walking video, so buttress positions come from the camera path and spacing is measured without the plot drawing. | Z19: TAP photo per stretch with a count. | AA19: Plot drawing (wall lengths); buttress spacing standard. | AB19: Spacing at or under the spec | AD19: =INDEX(Methods!$D$2:$D$11,MATCH(Q19,Methods!$A$2:$A$11,0)) -> 120 | AE19: Not started | AL19: 442ef689-57e1-4c31-84d5-d54a595305ca
A20: 108 | B20: Compound wall | C20: Block work and plastering compound wall | D20: Height & Width of compound wall is as per specification. | E20: COMPOUND WALL(Post Wall) | F20: Tape | G20: CRITICAL | H20: No | J20: One-time | K20: No | L20: No | M20: Size against drawing | N20: Wall height; wall thickness. | P20: Measurement | Q20: EXT | R20: Partial | S20: Medium | U20: To be decided | W20: Height from the exterior capture with the camera height known (about ±30 mm). Thickness needs a view of the top or an end: one TAP photo with a block as the scale. | X20: Helps | Y20: Ground plane and poses give the wall height from the walking video; a hit test on the wall top in a close-up gives the thickness. | Z20: BT laser meter. | AA20: Spec height and width. | AB20: ± 25 mm | AD20: =INDEX(Methods!$D$2:$D$11,MATCH(Q20,Methods!$A$2:$A$11,0)) -> 120 | AE20: Not started | AL20: bc6e0ab5-392e-4e22-8d9d-da7501956afa
A21: 109 | B21: Compound wall | C21: Block work and plastering compound wall | D21: Plastering surface is level and free from undulations. | E21: COMPOUND WALL(Post Wall) | F21: Tools | G21: CRITICAL | H21: No | J21: One-time | K21: No | L21: No | M21: Surface finish | N21: Gross undulations, patches and cracks in the plaster. | Q21: EXT | R21: Partial | S21: Low | U21: To be decided | W21: The vision model reads the exterior frames for gross undulations, patches and cracks, best in low sun or with a torch at a grazing angle. Millimetre flatness is not visible. | X21: Helps | Y21: Poses let the frames be rectified per stretch of wall for the vision model. No help with flatness. | Z21: MANUAL 2 m straightedge, reading recorded in the app. | AA21: None. | AB21: About 3 mm under a 2 m straightedge | AD21: =INDEX(Methods!$D$2:$D$11,MATCH(Q21,Methods!$A$2:$A$11,0)) -> 120 | AE21: Not started | AL21: fba86fa1-ea2a-4af4-a7e4-f0af5f95ced7
A22: 110 | B22: Compound wall | C22: Completion of SSM (If SSM under compound beam) | D22: SSM top level and width to be checked | E22: COMPOUND WALL(Post Wall) | F22: Tape | G22: CRITICAL | H22: No | J22: One-time | K22: No | L22: No | M22: Height and position | N22: Top level of the SSM against the datum; width. | Q22: MANUAL | R22: Manual | S22: Low | T22: Low | U22: To be decided | W22: Levels need an instrument. The SE records the auto-level or laser readings in the app with a photo. Width from a TAP photo with a tape. | X22: No | Y22: A level-instrument job. ARCore planes are good to a few cm, far from a level's millimetres. | Z22: A BT laser level with a receiver could feed the app directly. | AA22: Drawing (level, width). | AB22: Per drawing | AD22: =INDEX(Methods!$D$2:$D$11,MATCH(Q22,Methods!$A$2:$A$11,0)) -> 60 | AE22: Not started | AL22: 7d2bc1aa-e54e-4453-b014-535a27d5da9d
A23: 111 | B23: Compound wall | C23: PCC for SSM (If SSM under compound beam) | D23: SSM layout to be checked | E23: COMPOUND WALL(Post Wall) | F23: Tape | G23: CRITICAL | H23: No | J23: One-time | K23: No | L23: No | M23: Size against drawing | N23: Footing positions against the plan. | Q23: MANUAL | R23: Evidence | S23: Low | T23: Low | U23: To be decided | W23: Photo of the laid-out lines with the tape and the drawing, kept as the record. | X23: Helps | Y23: An optional AR measure action: the SE taps the footing corners and a hit test returns their positions to a few cm for an overlay on the plan. | Z23: A photo from an elevated point (first floor or terrace) with four marked reference points can be warped onto the plan for a direct overlay. | AA23: Foundation plan. | AB23: Per drawing | AD23: =INDEX(Methods!$D$2:$D$11,MATCH(Q23,Methods!$A$2:$A$11,0)) -> 60 | AE23: Not started | AL23: edc4737e-d143-4300-946e-11589541d450
A24: 123 | B24: Doors & Windows | C24: Windows and Doors installation | D24: Doors/ windows/ ventilator grill fixing finishing is uniform | E24: POST PUTTY | F24: Tape | G24: REGULAR | H24: No | J24: One-time | K24: No | L24: Yes | M24: Surface finish | N24: Even gaps, clean sealant line, no visible fasteners or damage. | Q24: G-VIS | R24: Full | S24: Medium | T24: High | U24: Gyro + Gemini: appearance | V24: Select the gyro frames that show the doors, windows and grills; Gemini checks that the finishing is uniform. | W24: The vision model reads a crop of each door, window and grill from the gyro frames with a short rubric: gap evenness, sealant line, fastener heads, scratches, damage. | X24: Helps | Y24: A rectified per-opening crop from the poses makes even gaps easier to judge. The judgement itself is still visual. | Z24: TAP close-up where the model is unsure. | AA24: Finish rubric (what uniform means for your packages). | AB24: Rubric pass | AD24: =INDEX(Methods!$D$2:$D$11,MATCH(Q24,Methods!$A$2:$A$11,0)) -> 0 | AE24: Not started | AL24: 298f35ed30e44a9395614cef23eef52b
A25: 125 | B25: Doors & Windows | C25: Windows and Doors installation | D25: Doors/windows/ventilators are as per specified size and design | E25: POST PUTTY | F25: Tape | G25: REGULAR | H25: No | J25: One-time | K25: No | L25: Yes | M25: Size against drawing | N25: Frame width and height; design against spec. | Q25: G-GEO | R25: Full | S25: Medium | T25: Low | U25: To be decided | W25: Width and height of each frame from the rectified wall (about ±30 mm separates catalogue sizes such as 900 and 1000 mm). Design matched by the vision model against the BOQ line or a reference image for the package (type, material, track count, mesh). | X25: Core | Y25: Wall plane and intrinsics give frame width and height in mm; the floor plane gives the sill height. The design match stays with the vision model. | Z25: TAP with a tape for borderline sizes. | AA25: Door and window schedule; BOQ or package spec with reference images. | AB25: Size ± 25 mm; design must match | AD25: =INDEX(Methods!$D$2:$D$11,MATCH(Q25,Methods!$A$2:$A$11,0)) -> 0 | AE25: Not started | AL25: bb228272843f424e8719dbd72218d8c1
A26: 127 | B26: Doors & Windows | C26: Windows and Doors installation | D26: Doors/windows/ventilators shutters are fine, in level and latches when closed | E26: POST PUTTY | F26: Tape | G26: REGULAR | H26: No | J26: One-time | K26: No | L26: Yes | M26: Functional | N26: Shutter alignment and gaps; latching. | Q26: G-VIS | R26: Partial | S26: Medium | T26: High | U26: Gyro + Gemini: appearance | V26: Select the gyro frames that show the shutters; Gemini checks alignment and level. Latching still needs the SE. | W26: Ask the SE to close all shutters before the gyro capture; the vision model then checks even gaps and alignment. Latching is a one-tap confirmation per door and window. | X26: Helps | Y26: Gravity frame lets the shutter's top edge be checked for level in the same view. The latch test stays a tap. | Z26: IMU: phone laid on the shutter's top edge for level. A short video of the latch. | AA26: None. | AB26: Even gap; latch engages | AD26: =INDEX(Methods!$D$2:$D$11,MATCH(Q26,Methods!$A$2:$A$11,0)) -> 0 | AE26: Not started | AL26: a599e957e81243c0a7223dcdbfb05068
A27: 128 | B27: Doors & Windows | C27: Windows and Doors installation | D27: Door/Windows/Ventilator are placed as per the drawings and the sill height is good | E27: POST PUTTY | F27: Tape | G27: REGULAR | H27: No | J27: One-time | K27: No | L27: Yes | M27: Height and position | N27: Opening position along the wall; sill height. | P27: 7ft (Depends on the door/window size in floor plan) | Q27: G-GEO | R27: Full | S27: High | T27: Low | U27: To be decided | W27: Each opening is located on its wall from the layout (distance from the corner) and its sill height is read, both compared with the drawing. | X27: Core | Y27: Poses and wall planes place each opening on the floor plan; the floor plane gives the sill height. | Z27: TAP with a tape. | AA27: Floor plan and window schedule. | AB27: Position ± 50 mm; sill ± 25 mm | AD27: =INDEX(Methods!$D$2:$D$11,MATCH(Q27,Methods!$A$2:$A$11,0)) -> 0 | AE27: Not started | AL27: d9b51ac715df43b983131a0033fd65ed
A28: 171 | B28: Fabrication works | C28: Fabrication works - Staircase and Balcony railing , Chamber covers, Gate complete | D28: check for chamber cover specifications | E28: Fabrication(Post Puttyl) | F28: Tape | G28: REGULAR | H28: No | J28: One-time | K28: No | L28: Yes | M28: Presence and spec match | N28: Chamber cover size, type and material. | Q28: TAP | R28: Partial | S28: Medium | T28: Low | U28: To be decided | W28: One photo per chamber with a tape or a known tile in frame. The vision model checks type and material against the spec (RCC, CI, SFRC, frame); size from the reference object. | X28: Helps | Y28: During the close-up, a hit test gives the camera-to-cover distance, so the pixel scale is known without a tape in frame. | Z28: Include the chambers in the exterior capture (EXT). | AA28: BOQ spec for chamber covers. | AB28: As per spec | AD28: =INDEX(Methods!$D$2:$D$11,MATCH(Q28,Methods!$A$2:$A$11,0)) -> 30 | AE28: Not started | AL28: ff808081818cac9e01818cb0c03c00f2
A29: 172 | B29: Fabrication works | C29: Fabrication works - Staircase and Balcony railing , Chamber covers, Gate complete | D29: Check for height, verticality,alignment&Spacing | E29: Fabrication(Post Puttyl) | F29: Tape | G29: REGULAR | H29: No | J29: One-time | K29: No | L29: Yes | M29: Size against drawing | N29: Railing height; baluster spacing; post plumb. | Q29: G-GEO | R29: Partial | S29: Medium | T29: Low | U29: New action: photo with tape or tool | V29: SE takes a photo with the measuring tape on the railing. | W29: Needs the staircase and balcony as capture points. Height from the floor line (about ±20 mm), spacing from the rectified view scaled by the railing height, posts checked against gravity. | X29: Core | Y29: Floor plane (or the stair-tread plane) gives the railing height; poses tie the frames along the stair; gravity gives post plumb. | Z29: TAP with a tape; BT-TOOL on flagged posts. | AA29: Railing spec (height, maximum gap). | AB29: Height ± 20 mm; gap at or under spec | AD29: =INDEX(Methods!$D$2:$D$11,MATCH(Q29,Methods!$A$2:$A$11,0)) -> 0 | AE29: Not started | AL29: ff808081818cac9e01818cb0c03c00ed
A30: 176 | B30: Fabrication works | C30: Fabrication works - Staircase and Balcony railing , Chamber covers, Gate complete | D30: Check for welding thickness & joints | E30: Fabrication(Post Puttyl) | F30: Tape | G30: REGULAR | H30: No | J30: One-time | K30: No | L30: Yes | M30: Workmanship defect | N30: Weld surface quality; throat thickness. | Q30: TAP | R30: Partial | S30: Low | T30: High | U30: Gyro + Gemini: appearance | V30: Select the gyro frames that show the welded joints; Gemini checks them. | W30: Close-up photos of the joints; the vision model screens for porosity, spatter, undercut, incomplete fusion and grinding finish. Throat thickness needs a weld gauge. | X30: Helps | Y30: Hit-test distance gives the pixel scale for the close-up. Weld quality stays visual and throat thickness stays manual. | Z30: MANUAL gauge reading typed into the app. | AA30: Weld spec. | AB30: Per spec | AD30: =INDEX(Methods!$D$2:$D$11,MATCH(Q30,Methods!$A$2:$A$11,0)) -> 30 | AE30: Not started | AL30: ff808081818cac9e01818cb0c03c00ee
A31: 186 | B31: Final Miscellaneous works and cleaning | C31: Handover QA request raised | D31: Doors and windows are as per the contract. | E31: FINAL WORK(Post Puttyl) | F31: Tape | G31: CRITICAL | H31: No | J31: One-time | K31: No | L31: No | M31: Size against drawing | N31: Count, size and type of doors and windows per room against the contract. | Q31: G-GEO | R31: Full | S31: Medium | T31: High | U31: Gyro + Gemini: appearance | V31: Select the gyro frames that show the finished doors and windows; Gemini checks them against the contract. | W31: Same detector as ID 125, with the room's door and window list from the contract as the prompt input; also counts the items per room. | X31: Core | Y31: Same as ID 125. | Z31: TAP. | AA31: Contract door and window schedule. | AB31: Must match the contract | AC31: 125 | AD31: =INDEX(Methods!$D$2:$D$11,MATCH(Q31,Methods!$A$2:$A$11,0)) -> 0 | AE31: Not started | AL31: ff808081818cac9e01818cb0c03600b6
A32: 199 | B32: Flooring | C32: Bull marking for flooring along with Colour and pattern for tiles having been approved by Customer and surface preparation for dry areas | D32: Joints alignment/Pattern/Spacer usage have been discussed and approved by client. | E32: Flooring(Postwall) | F32: Tools | G32: CRITICAL | H32: Yes | I32: Space | J32: Floorwise | K32: Yes | L32: Yes | M32: Process and approval | N32: Client approval recorded. | O32: Should not be QC | P32: Should not be QC | Q32: ATTEST | R32: Evidence | S32: High | T32: Low | U32: Not a QC | V32: SE: should not be a QC; it is a client approval. | W32: Make this a client approval step in the app: the gyro frames of the bull-marked floor (or a layout render) go to the client, who approves with an OTP or a signature. The approval is the QC record. | X32: No | Y32: An approval record. | Z32: Site-visit sign-off photo. | AA32: Tile layout drawing. | AB32: Approval present | AD32: =INDEX(Methods!$D$2:$D$11,MATCH(Q32,Methods!$A$2:$A$11,0)) -> 10 | AE32: Not started | AL32: ff808081818cac9e01818cb0c034009f
A33: 206 | B33: Flooring | C33: Bull marking for flooring of wet areas along with bore packing | D33: The mortar bed should adjust the required slope before laying the tile. | E33: Flooring(Postwall) | F33: Tape | G33: REGULAR | H33: No | I33: Space | J33: Floorwise | K33: Yes | L33: Yes | M33: Slope | N33: Floor slope toward the drain. | Q33: IMU | R33: Partial | S33: Medium | T33: Low | U33: New action: phone IMU | V33: Lay the phone on the mortar bed and read the slope from the IMU. | W33: The SE lays the phone flat on the bed at two or three points (or on a straightedge). The accelerometer reads tilt to about 0.1°, enough for a 1 % slope (0.57°). The app records the direction toward the drain. | X33: No | Y33: The phone lies on the bed and the raw accelerometer is the instrument; ARCore is not running and not needed. | Z33: ATTEST: a short video of water or a marble running to the drain. | AA33: Required slope (for example 1:100). | AB33: Slope at or above spec, toward the drain | AD33: =INDEX(Methods!$D$2:$D$11,MATCH(Q33,Methods!$A$2:$A$11,0)) -> 20 | AE33: Not started | AL33: 8a7483bc8adaa888018add7add9e0019
A34: 207 | B34: Flooring | C34: Flooring in Dry areas | D34: Are the joints properly aligned? | E34: Flooring(Postwall) | F34: Tools | G34: CRITICAL | H34: Yes | I34: Space | J34: Floorwise | K34: Yes | L34: Yes | M34: Alignment and straightness | N34: Grout-line straightness and offset at intersections. | O34: Can do without tools move to GYRO | Q34: G-FLOOR | R34: Full | S34: High | T34: High | U34: Gyro + Gemini: geometry | V34: Select the gyro frames that show the floor; Gemini checks the joint alignment. SE: can be done without tools, move to gyro. | W34: Warp the downward gyro band into a top-down floor image, detect the grout lines, fit the grid and report the largest offset at intersections and the line waviness (tile size is the ruler, about 1 mm resolution). Lippage does not show. | X34: Core | Y34: Floor plane and poses give the exact top-down warp of the downward band, so grout-line offsets measure in mm with the tile as the ruler. | Z34: TAP photo with a torch at a grazing angle for lippage; MANUAL straightedge. | AA34: Tile size; spacer width. | AB34: Offset at or under 1 mm | AD34: =INDEX(Methods!$D$2:$D$11,MATCH(Q34,Methods!$A$2:$A$11,0)) -> 0 | AE34: Not started | AL34: ff808081818cac9e01818cb0c03400a4
A35: 216 | B35: Flooring | C35: Flooring in Dry areas | D35: Skirting to be fixed as per specification and to the standard height | E35: Flooring(Postwall) | F35: Tape | G35: REGULAR | H35: No | I35: Space | J35: Floorwise | K35: Yes | L35: Yes | M35: Height and position | N35: Skirting height and uniformity; material. | Q35: G-GEO | R35: Full | S35: High | T35: High | U35: Gyro + Gemini: height | V35: Select the gyro frames that show the skirting; Gemini checks the height against the standard (note says 3 to 4 feet). | W35: Skirting top edge detected along each wall; height from the floor line with the adjacent tile as the ruler (about ±5 mm). Material and finish judged by the vision model. | X35: Core | Y35: Floor plane gives the height reference; poses and the wall plane place the skirting edge. | Z35: TAP with a tape. | AA35: Skirting height and material from spec (for example 100 mm). | AB35: ± 5 mm | AD35: =INDEX(Methods!$D$2:$D$11,MATCH(Q35,Methods!$A$2:$A$11,0)) -> 0 | AE35: Not started | AL35: fe28ef55-3e1d-4cd3-b8b8-cb4582d8a74e
A36: 219 | B36: Flooring | C36: Flooring in wet areas | D36: Balcony/ Bathroom: Tiles is cut as per the grating - square / circle | E36: Flooring(Postwall) | F36: Tools | G36: REGULAR | H36: No | I36: Space | J36: Floorwise | K36: Yes | L36: Yes | M36: Workmanship defect | N36: Cut shape and fit around gratings. | Q36: G-VIS | R36: Full | S36: Medium | T36: High | U36: Gyro + Gemini: appearance | V36: Select the gyro frames that show the drain; Gemini checks the tile cut. | W36: The vision model reads the downward-band crop around each drain: shape matches the grating, cut edges clean, gap even. | X36: Helps | Y36: Floor plane and poses give an undistorted top-down crop around each drain for the vision model. | Z36: TAP when the drain is small or far from the tripod. | AA36: Grating type per bathroom and balcony. | AB36: Rubric pass | AD36: =INDEX(Methods!$D$2:$D$11,MATCH(Q36,Methods!$A$2:$A$11,0)) -> 0 | AE36: Not started | AL36: ff808081818cac9e01818cb0c034009d
A37: 222 | B37: Flooring | C37: Flooring in wet areas | D37: Joints alignment/Pattern/Spacer usage have been discussed and approved by client. | E37: Flooring(Postwall) | F37: Tools | G37: CRITICAL | H37: Yes | I37: Space | J37: Floorwise | K37: Yes | L37: Yes | M37: Process and approval | N37: Client approval recorded. | Q37: ATTEST | R37: Evidence | S37: High | U37: Not a QC | V37: Same check as ID 199; SE: should not be a QC. | W37: Same approval flow as ID 199, for wet areas. | X37: No | Y37: An approval record. | Z37: Site-visit sign-off photo. | AA37: Tile layout drawing. | AB37: Approval present | AC37: 199 | AD37: =INDEX(Methods!$D$2:$D$11,MATCH(Q37,Methods!$A$2:$A$11,0)) -> 10 | AE37: Not started | AL37: ff808081818cac9e01818cb0c034009f
A38: 272 | B38: Internal & External Painting - Final coat, Plumbing fittings | C38: Final coat of painting, CP fittings installation complete | D38: Check for thickness of the granite is as per the requirement. | E38: POST PUTTY | F38: Tape | G38: REGULAR | H38: No | J38: One-time | K38: No | L38: Yes | M38: Thickness and joints | N38: Counter slab thickness at the exposed edge. | Q38: TAP | R38: Partial | S38: Medium | U38: To be decided | W38: One close-up of the counter edge with a coin or a printed scale sticker in frame; thickness in pixels converted by the reference. | X38: Helps | Y38: Hit-test distance to the counter edge gives the pixel scale. A coin in frame remains the safer reference at ±1 mm. | Z38: MANUAL vernier or tape reading. | AA38: Spec thickness (for example 18 or 20 mm). | AB38: ± 1 mm | AD38: =INDEX(Methods!$D$2:$D$11,MATCH(Q38,Methods!$A$2:$A$11,0)) -> 30 | AE38: Not started | AL38: 432fe711-b9bf-460f-90c7-2b2e5a5d4a72
A39: 274 | B39: Internal & External Painting - Final coat, Plumbing fittings | C39: Final coat of painting, CP fittings installation complete | D39: Check whether the provision is made for sink fixing | E39: POST PUTTY | F39: Tape | G39: REGULAR | H39: No | J39: One-time | K39: No | L39: Yes | M39: Presence and spec match | N39: Cut-out, brackets or clamps, and water and waste points at the sink location. | Q39: G-VIS | R39: Full | S39: High | T39: High | U39: Gyro + Gemini: appearance | V39: Take frames from the gyro and ask Gemini. | W39: The vision model reads the kitchen counter crop from the gyro frames: cut-out present and sized, support brackets, tap and waste points in place. | X39: No | Y39: Visual presence check; the ordinary frames are enough. | Z39: TAP. | AA39: Sink type from spec. | AB39: All items present | AD39: =INDEX(Methods!$D$2:$D$11,MATCH(Q39,Methods!$A$2:$A$11,0)) -> 0 | AE39: Not started | AL39: 5b7a47ea-ef58-46f5-9128-5fe0c812150c
A40: 286 | B40: Internal & External Painting - Final coat, Plumbing fittings | C40: Final coat of painting, CP fittings installation complete | D40: Railing Material adheres to the specifications and are as per the package | E40: POST PUTTY | F40: Tape | G40: REGULAR | H40: No | J40: One-time | K40: No | L40: Yes | M40: Presence and spec match | N40: Railing material type and profile against the package. | Q40: G-VIS | R40: Partial | S40: Medium | U40: To be decided | W40: The vision model compares the railing with the package spec and reference image (stainless, mild steel or glass; profile sizes). The steel grade (304 against 202) is not visible. | X40: No | Y40: Visual match against the spec; no measurement involved. | Z40: MANUAL: invoice or material test certificate check. | AA40: Package spec with reference images. | AB40: Must match the package | AD40: =INDEX(Methods!$D$2:$D$11,MATCH(Q40,Methods!$A$2:$A$11,0)) -> 0 | AE40: Not started | AL40: bccee11b-603c-4d3b-bb34-f0a748a17901
...

Sheet Methods
A1: Code | B1: Method | C1: What the SE does differently | D1: Extra SE time per use (s) | E1: Accuracy you can expect | F1: Build effort (S/M/L) | G1: Checks using it | H1: Limits and notes
A2: G-VIS | B2: Gyro frames to vision model | C2: Nothing new. The existing gyro capture is used. | D2: 0 | E2: Qualitative. Reliable for presence, finish, gross defects and matching an item to a written spec or reference image. | F2: M | G2: =COUNTIF('QC Tracker'!$Q$3:$Q$200,A2) -> 8 | H2: Does not measure. Give it the drawing or spec text in the prompt and ask for pass, flag or needs-a-photo.
A3: G-GEO | B3: Gyro to metric geometry | C3: Nothing new, provided the tripod height is fixed or the floor-to-ceiling height from the drawing is available. | D3: 0 | E3: About ±20–30 mm at 3 m for heights, sizes and positions on a wall; about ±5 mm when a tile or block in the scene is used as the ruler. | F3: L | G3: =COUNTIF('QC Tracker'!$Q$3:$Q$200,A3) -> 19 | H3: Needs gravity-aligned frames, a room-layout model and a known camera height. Lengths across the view (widths) are less accurate than heights.
A4: G-PLUMB | B4: Gyro plumb, level and straightness screening | C4: Nothing new. | D4: 0 | E4: About ±0.2°, which is ±7 mm over 2 m. A screening tool for gross errors, not a plumb-bob replacement. | F4: M | G4: =COUNTIF('QC Tracker'!$Q$3:$Q$200,A4) -> 14 | H4: Only in-plane deviation is visible. A wall bowing toward or away from the camera does not show as a slanted line.
A5: G-FLOOR | B5: Gyro to top-down floor image | C5: Optionally one extra band at about −70° so the floor near the tripod is covered. | D5: 0 | E5: About 1 mm for in-plane alignment when the tile size is used as the ruler. | F5: M | G5: =COUNTIF('QC Tracker'!$Q$3:$Q$200,A5) -> 1 | H5: Lippage (height steps between tiles) does not show from above.
A6: TAP | B6: Requested close-up photo | C6: Takes one photo when the app asks, with a tile, block, coin or scale sticker in frame. | D6: 30 | E6: About 0.3–0.5 mm with a reference object in frame. | F6: S | G6: =COUNTIF('QC Tracker'!$Q$3:$Q$200,A6) -> 4 | H6: Keep requests rare: only checks that always need one, or when the vision model reports it is unsure.
A7: IMU | B7: Phone as a level | C7: Lays the phone flat on the surface for two seconds, at two or three points. | D7: 20 | E7: About ±0.1° (1 mm per metre) after a one-time calibration. | F7: S | G7: =COUNTIF('QC Tracker'!$Q$3:$Q$200,A7) -> 1 | H7: Needs a flat phone back or a flat case. Good for slopes of 1 % and above.
A8: BT-TOOL | B8: Bluetooth laser meter or digital level | C8: Takes the reading with the tool; the app receives it over Bluetooth. | D8: 30 | E8: Millimetre grade. | F8: M | G8: =COUNTIF('QC Tracker'!$Q$3:$Q$200,A8) -> 0 | H8: Hardware cost per SE. Best used only on items the gyro screening has flagged.
A9: EXT | B9: Exterior capture | C9: One walking video along the compound wall, or gyro captures at two or three points in the plot. Once per site. | D9: 120 | E9: Same as G-GEO and G-VIS, applied outdoors. | F9: M | G9: =COUNTIF('QC Tracker'!$Q$3:$Q$200,A9) -> 3 | H9: New action in the app. Strong sun and shadows need a prompt that tolerates them.
A10: ATTEST | B10: One-tap confirmation with evidence | C10: Taps yes and attaches a photo, a short video or a voice note; or the client approves in the app. | D10: 10 | E10: A process record, not a measurement. | F10: S | G10: =COUNTIF('QC Tracker'!$Q$3:$Q$200,A10) -> 3 | H10: Use for process checks and approvals where no image after the fact can prove the point.
A11: MANUAL | B11: Stays with the SE and a physical tool | C11: Takes the reading as today and types or dictates it into the app. | D11: 60 | E11: Tool grade. | F11: S | G11: =COUNTIF('QC Tracker'!$Q$3:$Q$200,A11) -> 2 | H11: The app still gets a structured record and a photo, so the check is not lost.

Sheet Dashboard
A1: QC automation dashboard
A2: Every figure is a formula over the QC Tracker tab. Edit there, not here.
A4: Key figures | B4: Value | D4: Status | E4: Checks | F4: Share
A5: Total checks | B5: =COUNTA('QC Tracker'!$A$3:$A$200) -> 55 | D5: Not started | E5: =COUNTIF('QC Tracker'!$AE$3:$AE$200,D5) -> 55 | F5: =IF($B$5=0,0,E5/$B$5) -> 1
A6: Distinct detectors to build (rows without a 'same detector as' pointer) | B6: =COUNTA('QC Tracker'!$A$3:$A$200)-COUNTA('QC Tracker'!$AC$3:$AC$200) -> 42 | D6: Exploring | E6: =COUNTIF('QC Tracker'!$AE$3:$AE$200,D6) -> 0 | F6: =IF($B$5=0,0,E6/$B$5) -> 0
A7: Checks needing no new site action (G- methods) | B7: =SUMPRODUCT((LEFT('QC Tracker'!$Q$3:$Q$200,2)="G-")*1) -> 42 | D7: Prototype | E7: =COUNTIF('QC Tracker'!$AE$3:$AE$200,D7) -> 0 | F7: =IF($B$5=0,0,E7/$B$5) -> 0
A8: Share needing no new site action | B8: =IF(B5=0,0,B7/B5) -> 0.76363636 | D8: Validating | E8: =COUNTIF('QC Tracker'!$AE$3:$AE$200,D8) -> 0 | F8: =IF($B$5=0,0,E8/$B$5) -> 0
A9: Critical checks | B9: =COUNTIF('QC Tracker'!$G$3:$G$200,"CRITICAL") -> 27 | D9: Live | E9: =COUNTIF('QC Tracker'!$AE$3:$AE$200,D9) -> 0 | F9: =IF($B$5=0,0,E9/$B$5) -> 0
A10: Critical checks with Full automation | B10: =COUNTIFS('QC Tracker'!$G$3:$G$200,"CRITICAL",'QC Tracker'!$R$3:$R$200,"Full") -> 7 | D10: Parked | E10: =COUNTIF('QC Tracker'!$AE$3:$AE$200,D10) -> 0 | F10: =IF($B$5=0,0,E10/$B$5) -> 0
A11: No-go checks | B11: =COUNTIF('QC Tracker'!$H$3:$H$200,"Yes") -> 5 | D11: Total | E11: =SUM(E5:E10) -> 55 | F11: =IF($B$5=0,0,E11/$B$5) -> 1
A12: No-go checks covered (Full or Evidence) | B12: =COUNTIFS('QC Tracker'!$H$3:$H$200,"Yes",'QC Tracker'!$R$3:$R$200,"Full")+COUNTIFS('QC Tracker'!$H$3:$H$200,"Yes",'QC Tracker'!$R$3:$R$200,"Evidence") -> 5
A13: Added SE time if every check runs its primary method (s, upper bound) | B13: =SUM('QC Tracker'!$AD$3:$AD$200) -> 650 | D13: Automation level | E13: Checks | F13: Of which critical | G13: Of which no-go
A14: Same, in minutes | B14: =B13/60 -> 10.833333 | D14: Full | E14: =COUNTIF('QC Tracker'!$R$3:$R$200,D14) -> 18 | F14: =COUNTIFS('QC Tracker'!$R$3:$R$200,D14,'QC Tracker'!$G$3:$G$200,"CRITICAL") -> 7 | G14: =COUNTIFS('QC Tracker'!$R$3:$R$200,D14,'QC Tracker'!$H$3:$H$200,"Yes") -> 2
A15: Checks Live | B15: =COUNTIF('QC Tracker'!$AE$3:$AE$200,"Live") -> 0 | D15: Partial | E15: =COUNTIF('QC Tracker'!$R$3:$R$200,D15) -> 32 | F15: =COUNTIFS('QC Tracker'!$R$3:$R$200,D15,'QC Tracker'!$G$3:$G$200,"CRITICAL") -> 15 | G15: =COUNTIFS('QC Tracker'!$R$3:$R$200,D15,'QC Tracker'!$H$3:$H$200,"Yes") -> 0
A16: Share Live | B16: =IF(B5=0,0,B15/B5) -> 0 | D16: Evidence | E16: =COUNTIF('QC Tracker'!$R$3:$R$200,D16) -> 4 | F16: =COUNTIFS('QC Tracker'!$R$3:$R$200,D16,'QC Tracker'!$G$3:$G$200,"CRITICAL") -> 4 | G16: =COUNTIFS('QC Tracker'!$R$3:$R$200,D16,'QC Tracker'!$H$3:$H$200,"Yes") -> 3
D17: Manual | E17: =COUNTIF('QC Tracker'!$R$3:$R$200,D17) -> 1 | F17: =COUNTIFS('QC Tracker'!$R$3:$R$200,D17,'QC Tracker'!$G$3:$G$200,"CRITICAL") -> 1 | G17: =COUNTIFS('QC Tracker'!$R$3:$R$200,D17,'QC Tracker'!$H$3:$H$200,"Yes") -> 0
D18: Total | E18: =SUM(E14:E17) -> 55 | F18: =SUM(F14:F17) -> 27 | G18: =SUM(G14:G17) -> 5
A19: Primary method | B19: Checks | C19: Added SE time (s)
A20: =Methods!A2 -> G-VIS | B20: =COUNTIF('QC Tracker'!$Q$3:$Q$200,A20) -> 8 | C20: =SUMIF('QC Tracker'!$Q$3:$Q$200,A20,'QC Tracker'!$AD$3:$AD$200) -> 0
A21: =Methods!A3 -> G-GEO | B21: =COUNTIF('QC Tracker'!$Q$3:$Q$200,A21) -> 19 | C21: =SUMIF('QC Tracker'!$Q$3:$Q$200,A21,'QC Tracker'!$AD$3:$AD$200) -> 0 | D21: Confidence | E21: Checks
A22: =Methods!A4 -> G-PLUMB | B22: =COUNTIF('QC Tracker'!$Q$3:$Q$200,A22) -> 14 | C22: =SUMIF('QC Tracker'!$Q$3:$Q$200,A22,'QC Tracker'!$AD$3:$AD$200) -> 0 | D22: High | E22: =COUNTIF('QC Tracker'!$S$3:$S$200,D22) -> 16
A23: =Methods!A5 -> G-FLOOR | B23: =COUNTIF('QC Tracker'!$Q$3:$Q$200,A23) -> 1 | C23: =SUMIF('QC Tracker'!$Q$3:$Q$200,A23,'QC Tracker'!$AD$3:$AD$200) -> 0 | D23: Medium | E23: =COUNTIF('QC Tracker'!$S$3:$S$200,D23) -> 33
A24: =Methods!A6 -> TAP | B24: =COUNTIF('QC Tracker'!$Q$3:$Q$200,A24) -> 4 | C24: =SUMIF('QC Tracker'!$Q$3:$Q$200,A24,'QC Tracker'!$AD$3:$AD$200) -> 120 | D24: Low | E24: =COUNTIF('QC Tracker'!$S$3:$S$200,D24) -> 6
A25: =Methods!A7 -> IMU | B25: =COUNTIF('QC Tracker'!$Q$3:$Q$200,A25) -> 1 | C25: =SUMIF('QC Tracker'!$Q$3:$Q$200,A25,'QC Tracker'!$AD$3:$AD$200) -> 20
A26: =Methods!A8 -> BT-TOOL | B26: =COUNTIF('QC Tracker'!$Q$3:$Q$200,A26) -> 0 | C26: =SUMIF('QC Tracker'!$Q$3:$Q$200,A26,'QC Tracker'!$AD$3:$AD$200) -> 0
A27: =Methods!A9 -> EXT | B27: =COUNTIF('QC Tracker'!$Q$3:$Q$200,A27) -> 3 | C27: =SUMIF('QC Tracker'!$Q$3:$Q$200,A27,'QC Tracker'!$AD$3:$AD$200) -> 360 | E27: Stage | F27: Checks | G27: Critical | H27: Full automation | I27: Live
A28: =Methods!A10 -> ATTEST | B28: =COUNTIF('QC Tracker'!$Q$3:$Q$200,A28) -> 3 | C28: =SUMIF('QC Tracker'!$Q$3:$Q$200,A28,'QC Tracker'!$AD$3:$AD$200) -> 30 | E28: Casting the lintels,staircase, blockwork upto the slab level | F28: =COUNTIF('QC Tracker'!$B$3:$B$200,E28) -> 10 | G28: =COUNTIFS('QC Tracker'!$B$3:$B$200,E28,'QC Tracker'!$G$3:$G$200,"CRITICAL") -> 4 | H28: =COUNTIFS('QC Tracker'!$B$3:$B$200,E28,'QC Tracker'!$R$3:$R$200,"Full") -> 2 | I28: =COUNTIFS('QC Tracker'!$B$3:$B$200,E28,'QC Tracker'!$AE$3:$AE$200,"Live") -> 0
A29: =Methods!A11 -> MANUAL | B29: =COUNTIF('QC Tracker'!$Q$3:$Q$200,A29) -> 2 | C29: =SUMIF('QC Tracker'!$Q$3:$Q$200,A29,'QC Tracker'!$AD$3:$AD$200) -> 120 | E29: Column rising, blockwork upto lintel level | F29: =COUNTIF('QC Tracker'!$B$3:$B$200,E29) -> 6 | G29: =COUNTIFS('QC Tracker'!$B$3:$B$200,E29,'QC Tracker'!$G$3:$G$200,"CRITICAL") -> 4 | H29: =COUNTIFS('QC Tracker'!$B$3:$B$200,E29,'QC Tracker'!$R$3:$R$200,"Full") -> 1 | I29: =COUNTIFS('QC Tracker'!$B$3:$B$200,E29,'QC Tracker'!$AE$3:$AE$200,"Live") -> 0
A30: Total | B30: =SUM(B20:B29) -> 55 | C30: =SUM(C20:C29) -> 650 | E30: Compound wall | F30: =COUNTIF('QC Tracker'!$B$3:$B$200,E30) -> 5 | G30: =COUNTIFS('QC Tracker'!$B$3:$B$200,E30,'QC Tracker'!$G$3:$G$200,"CRITICAL") -> 5 | H30: =COUNTIFS('QC Tracker'!$B$3:$B$200,E30,'QC Tracker'!$R$3:$R$200,"Full") -> 0 | I30: =COUNTIFS('QC Tracker'!$B$3:$B$200,E30,'QC Tracker'!$AE$3:$AE$200,"Live") -> 0
E31: Doors & Windows | F31: =COUNTIF('QC Tracker'!$B$3:$B$200,E31) -> 4 | G31: =COUNTIFS('QC Tracker'!$B$3:$B$200,E31,'QC Tracker'!$G$3:$G$200,"CRITICAL") -> 0 | H31: =COUNTIFS('QC Tracker'!$B$3:$B$200,E31,'QC Tracker'!$R$3:$R$200,"Full") -> 3 | I31: =COUNTIFS('QC Tracker'!$B$3:$B$200,E31,'QC Tracker'!$AE$3:$AE$200,"Live") -> 0
E32: Fabrication works | F32: =COUNTIF('QC Tracker'!$B$3:$B$200,E32) -> 3 | G32: =COUNTIFS('QC Tracker'!$B$3:$B$200,E32,'QC Tracker'!$G$3:$G$200,"CRITICAL") -> 0 | H32: =COUNTIFS('QC Tracker'!$B$3:$B$200,E32,'QC Tracker'!$R$3:$R$200,"Full") -> 0 | I32: =COUNTIFS('QC Tracker'!$B$3:$B$200,E32,'QC Tracker'!$AE$3:$AE$200,"Live") -> 0
A33: Check family | B33: Checks | C33: Distinct detectors | E33: Final Miscellaneous works and cleaning | F33: =COUNTIF('QC Tracker'!$B$3:$B$200,E33) -> 1 | G33: =COUNTIFS('QC Tracker'!$B$3:$B$200,E33,'QC Tracker'!$G$3:$G$200,"CRITICAL") -> 1 | H33: =COUNTIFS('QC Tracker'!$B$3:$B$200,E33,'QC Tracker'!$R$3:$R$200,"Full") -> 1 | I33: =COUNTIFS('QC Tracker'!$B$3:$B$200,E33,'QC Tracker'!$AE$3:$AE$200,"Live") -> 0
A34: Alignment and straightness | B34: =COUNTIF('QC Tracker'!$M$3:$M$200,A34) -> 4 | C34: =SUMPRODUCT(('QC Tracker'!$M$3:$M$200=A34)*('QC Tracker'!$AC$3:$AC$200="")) -> 3 | E34: Flooring | F34: =COUNTIF('QC Tracker'!$B$3:$B$200,E34) -> 6 | G34: =COUNTIFS('QC Tracker'!$B$3:$B$200,E34,'QC Tracker'!$G$3:$G$200,"CRITICAL") -> 3 | H34: =COUNTIFS('QC Tracker'!$B$3:$B$200,E34,'QC Tracker'!$R$3:$R$200,"Full") -> 3 | I34: =COUNTIFS('QC Tracker'!$B$3:$B$200,E34,'QC Tracker'!$AE$3:$AE$200,"Live") -> 0
A35: Functional | B35: =COUNTIF('QC Tracker'!$M$3:$M$200,A35) -> 1 | C35: =SUMPRODUCT(('QC Tracker'!$M$3:$M$200=A35)*('QC Tracker'!$AC$3:$AC$200="")) -> 1 | E35: Internal & External Painting - Final coat, Plumbing fittings | F35: =COUNTIF('QC Tracker'!$B$3:$B$200,E35) -> 3 | G35: =COUNTIFS('QC Tracker'!$B$3:$B$200,E35,'QC Tracker'!$G$3:$G$200,"CRITICAL") -> 0 | H35: =COUNTIFS('QC Tracker'!$B$3:$B$200,E35,'QC Tracker'!$R$3:$R$200,"Full") -> 1 | I35: =COUNTIFS('QC Tracker'!$B$3:$B$200,E35,'QC Tracker'!$AE$3:$AE$200,"Live") -> 0
